Workbook

Sheet 2026
A1: date | B1: details | C1: remarks | D1: Query Status
A2: 46024 | B2: Name: Amitava Mukherjee Phone: 8944966300 Email: mukherjeeamitava5@gmail.com Country: India City: Sonamukhi, Bankura district, West Bengal Hospital/Clinic: Sahara hospital Enquiry: I need a refurbished ct scan | C2: DONE
A3: 46024 | B3: Mehul 9023315200 MRI | C3: DONE
A4: 46024 | B4: 9973656973 Shyamesh Kumar Patna, Bihar Dealer | C4: DONE
A5: 46024 | B5: Kapil Yadav 98713 13052 C-arm -(cath lab part) dealer | C5: DONE
A6: 46024 | B6: Debdulal Nayak +91 98308 37298 Need CT scan | C6: DONE
A7: 46024 | B7: abhijeet pandey SAI Medicare +91 97957 63787 Required ct scan | C7: DONE
A8: 46024 | B8: Dr himmat yadav +91 99103 39898 | C8: DONE
A9: 46024 | B9: Shyam Sudar Seth +91 94314 64005 Bhabhua, Bihar | C9: DONE
A10: 46024 | B10: Dr Junaid Ahmed, Urooj hospital 8142730161 CT Injector Pump | C10: DONE
A11: 46024 | B11: ~Abdullah Ahmed +91 88129 36215 Kinggate Supperspeaciality Hospital . Goalpara town, Dist. Goalpara,Assam | C11: DONE
A12: 46025 | B12: Name: Rambabu Phone: 09347995052 Email: rambabu.sita@gmail.com Country: India City: VIJAYAWADA Hospital/Clinic: Enquiry: Please quote for WHOLE BODY MULTI SLICE C.T. SCANNER Activion (16 Slice) (One Re-furbished Complete System) | C12: DONE
A13: 46025 | B13: Dr Movil Gupta +91 816 833 3592 | C13: DONE
... A126: 46065 | B126: Dr dinesh +91 94481 57055 Kadur (chickmagalore district) Karnataka We are opening new one | C126: DONE
A127: 46066 | B127: ~Tsabeeh Abd Alwhab (Managaing Director of a company in Sudan) +249912683165 (available on whatsapp) Sudan (north africa) wants the catalogue of our products and discuss
A128: 46066 | B128: Dr. Sanjay Agrawal +91 79 7849 0955 Ramawtar Hospital Saraipali, Chhattisgarh | C128: DONE
A129: 46066 | B129: Happiness Yankho Mainala (stainly) +91 90418 85329 dealer may be - | C129: DONE
A130: 46066 | B130: Reconnect to Dr Jain (District kulgham, Kashmir) - - click here --
A131: 46066 | B131: Name: Mandeep Phone: 07773045677 Email: diagnosticstulsi@gmail.com Country: India City: SINGRAULI Hospital/Clinic: TULSI DIAGNOSTICS & PATHLABS | C131: DONE
A132: 46067 | B132: Vivek +91 81389 55147 ernakulam, kerala CT 128 slice -- Siemens somatom go up / ge revolution | C132: DONE
A133: 46067 | B133: nayan mohanty +91 832 904 5299 Maa medicare Baliapal - balasore, Odhisha MRI machine price | C133: DONE
A134: 46067 | B134: Dr. S.K Singh 8108011649 Lucknow dealer may be because he runs two company also | C134: DONE
A135: 46067 | B135: Ravindra Singh Swastick Biomedical Number: 9807656377 MRI Machine (dealer) | C135: DONE
A136: 46067 | B136: OP Goswami KR Traders +91 92153 31025 16 32 slice CT scan machine and MRI Dealer | C136: DONE
A137: 46070 | B137: Avinash Tyagi Tyagi Medicaid System +91 96250 25771 Kurukshetra Dealer | C137: DONE
A138: 46070 | B138: Bikash Kumar Om Sai Diagnostic Anvit medical Hzb Hazaribagh, Jharkhand +91 70703 31138 CT and MRI | C138: DONE
A139: 46070 | B139: ~Venugoopalreddy K Sunray Hospital +91 98661 23132 | C139: DONE
A140: 46070 | B140: ~Dr Shashi Gupta +91 92300 04261 Malda, West Bengal somatom model CT - Siemens | C140: DONE
A141: 7002605234 | B141: Name: Pugazh Sam Phone: 9629382399 Email: pugazhendhi1994@gmail.com City: Salem, Tamil Nadu Hospital/Clinic: ATHILA SCANS Enquiry: PLANNING TO EXPAND MY SCANS TO CT AND MRI. CAN YOU QUOTE ME THE PRICES OF CT AND MRI MACHINES | C141: DONE
A142: 46071 | B142: Dr Vikram Gautam +918445430839 CT Scan | C142: DONE
... A149: 46071 | B149: Niyas Nasar +91 98959 18011 New Care Scans and Diagnostic Kollam, Kerela | C149: DONE
A150: Akhilesh Prakash Shrivastva | B150: Pradip Tiwari 7002605234 Guwahati, Asssam CT scanner | C150: DONE
A151: 46072 | B151: Name: Anil Sonawane Phone: 9689770111 Email: anilsonawane@fidelitydaignostics.com Country: India City: PUNE Hospital/Clinic: Fidelity Diagnostics Pvt Ltd | C151: DONE
A152: 46072 | B152: Name: george warui Phone: +254721541387 Email: georgewarui08@gmail.com Country: Kenya City: Mombasa Enquiry: What is the best price for your machines, catalogue please | C152: DONE
A153: 46073 | B153: Akhilesh Prakash Shrivastava +91 72090 04029 CENTRAL X-RAY KENDRA, Rajendra Road, Barauni, Begusarai, Bihar, 851112 CT SCAN Needed | C153: DONE
A154: 46073 | B154: Name: Ramakrishna Phone: 9003811707 Country: India City: Coimbatore Hospital/Clinic: Ellen Hospital | C154: DONE
A155: 46073 | B155: Name: Krishna Phone: 9949325392 Email: chowdarybannu9@gmail.com Country: India City: Vijayawada Hospital/Clinic: Enquiry: We need Refurbished gamma camera, | C155: DONE
A156: 46074 | B156: Name: Shobhit Mishra Phone: 9654956414 Email: shobhit.m.x@gmail.com Country: India City: Deoria Enquiry: I am looking for CT scan machine | C156: DONE
A157: 46074 | B157: Name: M.ZUNED Memon Phone: +971585248185 Email: zuned@fettleintegrated.com Country: United Arab Emirates City: Dubai Enquiry: If u are interstednin buying Siemens Spectra 3T MRI 2017 please contact me. Wants to Sell | C157: will be handled by sir or ma'am
A158: 46074 | B158: Name: SYED MOSHARAF HOSSAIN Phone: 9732615531 Email: deep@smcbangla.com Country: india City: kolkata Hospital/Clinic: SMCH Enquiry: NEED CT & MRI | C158: DONE
...

Sheet International Leads
A1: 46027 | B1: Full name: Veralyn wilson Phone number: +18042010537 Email: Vc1nicethings@gmail.com City: Richmond, Virginia, USA | C1: will be handled by sir or ma'am/ Sachin Sir | D1: Vc1nicethings@gmail.com
A2: 46044 | B2: chandan chandan_gulati@yahoo.com +16473900452 Canada | C2: will be handled by sir or ma'am | D2: chandan_gulati@yahoo.com
A3: 46047 | B3: Name: Shahzad Gul & Felix Ripholz Phone: 004917655552779 Email: info@german-rays.com Country: Germany City: Stuttgart we have a Siemens MRI for sale (still cold) and wanted to know if this is interesting for you. Siemens PrismaFit 2014 Mit freundlichen Grüßen / Best Regards Shahzad Gul CEO -German Rays Medical Solutions Hertichstraße 37, 71229 Leonberg, Deutschland Mob: +49 162 6787 944 E-Mail: info@german-rays.com (to sell) | C3: will be handled by sir or ma'am | D3: info@german-rays.com ,
A4: 46053 | B4: Name: Adnan Phone: +967777107170 Email: adnan.awadi@yahoo.com Country: Yemen City: Sana'a Hospital/Clinic: Rowad alyemen Enquiry: Refurbished cath lab with neuro and peripheral vascular applications . | C4: will be handled by sir or ma'am | D4: adnan.awadi@yahoo.com
A5: 45719 | B5: Name: Moon Chaewon Phone: +17176866400 Email: moon.chaewon@accsgbl.com Country: Canada City: Toronto Hospital/Clinic: Access Global Group Enquiry: We are interested in your products, Kindly send us product prices and catalogue for immediate purchase. Best Regards. | C5: will be handled by sir or ma'am/ Sachin Sir | D5: moon.chaewon@accsgbl.com
A6: 45719 | B6: Name: D A TIFO Phone: +447903212347 Email: daahir1@live.com Country: United Kingdom City: Nairobi Hospital/Clinic: Diagnostic Centre Enquiry: Hello, | C6: will be handled by sir or ma'am/ Sachin Sir | D6: daahir1@live.com
A7: 45733 | B7: Tony Yiğit +12017371257 City:- Cliffside Park - borough Bergen County,- New Jersey, U.S.A erdoganceran9@gmail.com (service request) Source- Facebook Ads | C7: will be handled by sir or ma'am/ Sachin Sir | D7: erdoganceran9@gmail.com
A8: 45734 | B8: Ibrahim Sadek +17137137137 ibrahimsadek@gmail.com City- Houston, State - Texas USA Source- Facebook ads | C8: will be handled by sir or ma'am/ Sachin Sir | D8: ibrahimsadek@gmail.com
A9: 45736 | B9: Name: Mohan Patra Number: +8801723690188 Need: MRI or CT Machine Location: Bangladesh (dealer) | C9: will be handled by sir or ma'am/ Sachin Sir
A10: 45737 | B10: Name: Abd El Rahman Number: +966598846397 (whats up number) Location: Saudi Arabia Selling GE 1.5T MRI Machine 2009 Model | C10: will be handled by sir or ma'am/ Sachin Sir
A11: 45738 | B11: Name: HaMza Number: ‪+212722035394‬ Country: Casablanca, Morocco wants to sell philips cath machine Source: FB | C11: will be handled by sir or ma'am/ Sachin Sir
A12: 45742 | B12: Name: Juan nunez Phone: +18097070789 Email: juanlly1990@gmail.com , juanfcolly@hotmail.com City: San Francisco de Macoris Country: Dominican Republic Continent: North America, Carrebian Islands Hospital/Clinic: Centro de salud integral y díabetes (website leads) | C12: DONE - will be handled by sir or ma'am/ Sachin Sir | D12: juanlly1990@gmail.com , juanfcolly@hotmail.com
A13: 45747 | B13: ~Dr Irfan M Kasmani +265 999 45 57 86 Malawi, East Africa Cath Lab | C13: will be handled by sir or ma'am/ Sachin Sir
A14: 45749 | B14: Name: Eng-ALaa Althobhany Number: ‪+967779779280‬ Need: Siemens Gradient coil (Verio MRI) Location: Yemen But : coil need in Malaysia Source: FB | C14: will be handled by sir or ma'am/ Sachin Sir
A15: 45751 | B15: Full name- Jay Jenkins Phone number +17026014747 Email - jaiiii2@hotmail.com City- Las Vegas, Nevada, USA | C15: will be handled by sir or ma'am/ Sachin Sir | D15: jaiiii2@hotmail.com
A16: 45751 | B16: Name: Aaron Kuehl Phone: 4027874144 Email: akuehl@phasemedical.com Country: United States City: Omaha Enquiry: Price request for delivery to client in US | C16: will be handled by sir or ma'am/ Sachin Sir | D16: akuehl@phasemedical.com
A17: 45755 | B17: Name: Tauseef Khan Phone: +243993122307 Email: khan@nvceyanogoma.com Country:Congo, Demcratic Republic of Congo, Central Africa City: Kinshasa Hospital/Clinic:-Goma Tosif Khan Hospital Eyano Enquiry: Want to know about refurbished MRI and CT scan if you are willing to install in Africa (website form leads) | C17: will be handled by sir or ma'am/ Sachin Sir | D17: khan@nvceyanogoma.com
A18: 45762 | B18: Name: Ed Petrovskis Phone: +18479121644 Email: Edpetrovskis7@gmail.com Country: United States City: Itasca Hospital/Clinic: Enquiry: I came across your website and see that you have many CT Systems available. | C18: will be handled by sir or ma'am/ Sachin Sir | D18: Edpetrovskis7@gmail.com
A19: 45763 | B19: Gaurav Aggarwala Phone number +17138061487 Email- Tpatel@pulsephysicians.com City - The Woodlands, Texas | C19: will be handled by sir or ma'am/ Sachin Sir | D19: Tpatel@pulsephysicians.com
A20: 45763 | B20: Charlie Piccinnini Phone number +17327406413 Email cp4951@gmail.com City - Manhattan, New York | C20: will be handled by sir or ma'am/ Sachin Sir | D20: cp4951@gmail.com
A21: 45763 | B21: neil singh / satish Phone number +17143363588 Email - cbimaging007@gmail.com City - Anaheim, California | C21: will be handled by sir or ma'am/ Sachin Sir | D21: cbimaging007@gmail.com
A22: 45776 | B22: Name: les bridges Number: +447808587137 (whats up number) Country: United Kingdom Dealer of imaging equipment | C22: will be handled by sir or ma'am/ Sachin Sir
A23: 45777 | B23: Dominic langat ‪+254759165484‬ Kenya, | C23: will be handled by sir or ma'am/ Sachin Sir
A24: 45778 | B24: Gebret sadik +251918794733 Ethopia, East Africa MRI CT installation | C24: will be handled by sir or ma'am/ Sachin Sir-------- was asking for layout site planning
A25: 45780 | B25: ~Chris Piccinnini +17327406413 US (looking for spare parts) X-ray tubes for CT Akron Dura 532Q It’s for a Siemens Biograph 16 | C25: will be handled by sir or ma'am/ Sachin Sir
A26: 45780 | B26: Name: Kiko Ramos Phone: +34625313975 Email: 4dmedica@4dmedica.com Country: España City: Picassent Hospital/Clinic: 4d medica Enquiry: Hello. May I know the price ? Do you have brivo 385 or Revolution EVO 16 slices? | C26: will be handled by sir or ma'am/ Sachin Sir | D26: 4dmedica@4dmedica.com
A27: 45780 | B27: Name: rabea Phone: +963992292474 Email: rabemnasfe@gmail.com Country: syria City: damascus Hospital/Clinic: philips Enquiry: hello price plwase | C27: will be handled by sir or ma'am/ Sachin Sir | D27: rabemnasfe@gmail.com
A28: 45780 | B28: Otávio Pagnoncelli +5541992223607 Curitiba PR, Brazil (South America) looking for Siemens Essenza Dot warm system | C28: will be handled by sir or ma'am/ Sachin Sir
A29: 45782 | B29: Betim Sadriu +37744517811 Illinios--- (he has offices in Manaco(French region), Kosovo, Turkey and Bulgaria) Want to buy and sell multiple machines | C29: will be handled by sir or ma'am/ Sachin Sir
A30: 45782 | B30: Ahmed Tharwat +201113797283 Cairo, Egypt (Africa) I need closed MRI 1.5 T Preferably Siemens avanto | C30: will be handled by sir or ma'am/ Sachin Sir
A31: 45782 | B31: Tony +84938512355 Ho Chi Minh City, Vietnam (Southeast Asia) CT 16/32/128 Slices | C31: will be handled by sir or ma'am/ Sachin Sir
A32: 45783 | B32: ~Gianfranco Duro +393512424179 Global biomedical Servie Italy, (Europe) Want to discuss about possibilities of business partnership | C32: will be handled by sir or ma'am/ Sachin Sir
A33: 45784 | B33: Qazi Mansoor Ahmed +17347273539 qazilotus@hotmail.com detroit,Michigan, USA | C33: will be handled by sir or ma'am/ Sachin Sir | D33: qazilotus@hotmail.com
A34: 45784 | B34: Rafael Matiyas +14695038340 Matiyas50@gmail.com Garland, Dallas, Texas, USA | C34: will be handled by sir or ma'am/ Sachin Sir | D34: Matiyas50@gmail.com
A35: 45784 | B35: speedyROB +18885551212 rcpnow@gmail.com San diego, South California, USA | C35: will be handled by sir or ma'am/ Sachin Sir | D35: rcpnow@gmail.com
A36: 45786 | B36: Dayan Hernández Castro +12398348584 dayanhdezcastro@gmail.com naples, Florida, USA | C36: will be handled by sir or ma'am/ Sachin Sir | D36: dayanhdezcastro@gmail.com
A37: 45786 | B37: Name: Patrick sil Phone: 254742690544 Email: patricksila@radiologist.net Country: Kenya City: Nairobi Hospital/Clinic: Enquiry: Hello i would like to get a quotation for your machines. I would like a quotation for ceiling mounted xray machine, 64 and 32 slice ct scans, gama camera, and an mri machine. | C37: will be handled by sir or ma'am/ Sachin Sir | D37: patricksila@radiologist.net
A38: 45790 | B38: ~Sefiye +90 545 378 12 37 Turkey Wants to work as dealer and also provide spare parts -Siemens MRI parts repair ( Digital RF Transmitter and RFPA repairs. etc) | C38: will be handled by sir or ma'am/ Sachin Sir
A39: 45791 | B39: Otávio Pagnoncelli Muller +5541992223607 Curitiba, Brazil (South Brazil) Needs Part BRM-D gradient coil.(MRI - GE) | C39: will be handled by sir or ma'am/ Sachin Sir
A40: 45791 | B40: Name: Sabri Haj Email: Eng_sabri@hotmail.com Need: quotation of MRI Machine Profile: Director Sales Operations | Healthcare Expertise https://www.linkedin.com/in/sabri-haj-b413b87/ Location: Abu Dhabi Emirate, United Arab Emirates (we have his email only) | C40: will be handled by sir or ma'am/ Sachin Sir | D40: Eng_sabri@hotmail.com
...

Sheet 2025
A1: date | B1: details | C1: remarks | D1: Query Status
A2: 45659 | B2: Muteeb Showket Reshi +91 6280 915 890 Amritsar, Punjab CT | C2: DONE
A3: 45659 | B3: Forex Trader +91 89031 45543 | C3: DONE
A4: 45659 | B4: Yatoo Haziq +91 70515 81788 Jammu & Kashmir MRI | C4: DONE
A5: 45659 | B5: ~~Aurangzeb Khan +91 98916 80840 | C5: DONE
A6: 45659 | B6: palani +91 82204 18773 Chennai | C6: DONE
A7: 45663 | B7: Name- Prince tripathi Number:6391896168 Need: CT Machine Source:Fb | C7: DONE
A8: 45663 | B8: Sill Yzz +91 98836 41325 Price of the machine | C8: DONE
A9: 45663 | B9: ~Sujeet Singh +91 6394 580 713 MRI price | C9: DONE
A10: 45663 | B10: ~Himanshu Singh +91 98920 81412 Mumbai | C10: DONE
A11: 45663 | B11: ~Ravi kant roy +91 74885 80265 Gaya, Bihar (Want to sell his CT -GE BRIVO) | C11: DONE
A12: 45663 | B12: ~Dr Paaawan S Chordiya +91 74475 10041 | C12: DONE
A13: 45663 | B13: ~Dr Vivek Patil +91 99709 02590 Pune, Maharashtra pet scan machine | C13: DONE
... A418: 45778 | B418: ~Md, Danish +91 75995 65819 Greater Noida, Uttar Pradesh | C418: DONE
A419: 45778 | B419: Ebenezer Scan +91 93800 17113 Karnataka | C419: DONE | D419: Not responding
A420: 45778 | B420: Name: ABUSHIHADH Phone: 8089592949 Email: abushihadhmethalapeedika@gmail.com Country: India City: Kozhikode Hospital/Clinic: To be started Enquiry: I NEED KNOW ABOUT PRICE OF THE PRODUCT AND NEED KNOW THE ALL CHARGES INCLUDING INSTALLATION AND THE PRODUCTS COMES WITH THE PRODUCT (website lead) | C420: DONE | D420: No.not reachable
A421: 45778 | B421: Gebret sadik +251918794733 Ethopia, East Africa MRI CT installation | C421: will be handled by sir or ma'am/ Sachin Sir-------- was asking for layout site planning
A422: 45779 | B422: ~Dr. Raghavendra Shukla +91 94797 42550 Pratapgarh up | C422: DONE | D422: No.not connected/out of network coverage area
A423: 45779 | B423: ~Dr Parth Patel +91 78740 74987 Gujarat | C423: DONE
A424: 45779 | B424: Jaisumeet Singh Virk +91 94635 72532 SCIENCE VISION | C424: DONE
A425: 45779 | B425: Name:Raj Venu Gopal Number: 8220312183 Need: 3.0T MRI Machine profile: Dealer Source; FB (he is a dealer) | C425: DONE
A426: 45780 | B426: Ravinder Kalra +91 99973 19911 Agra, UP MRI | C426: DONE
A427: 45780 | B427: ~Manjunath +91 87926 40447 Bangalore,Karnartaka MRI | C427: DONE | D427: Not responding
A428: 45780 | B428: vatandeep lohan +91 90176 88117 Raman hospital kaithal, Haryana CT or cath lab | C428: DONE
A429: 45780 | B429: ~Chris Piccinnini +17327406413 US (looking for spare parts) X-ray tubes for CT Akron Dura 532Q It’s for a Siemens Biograph 16 | C429: will be handled by sir or ma'am/ Sachin Sir
A430: 45780 | B430: ~haji gulzar +91 70068 85636 Shopian, Kashmir Mri 1.5tesla | C430: DONE
A431: 45780 | B431: Name: Kiko Ramos Phone: +34625313975 Email: 4dmedica@4dmedica.com Country: España City: Picassent Hospital/Clinic: 4d medica Enquiry: Hello. May I know the price ? Do you have brivo 385 or Revolution EVO 16 slices? | C431: will be handled by sir or ma'am/ Sachin Sir
A432: 45780 | B432: Name: Ankit beniwal Phone: 89755 48383 Email: ankitbeniwal06@gmail.com Country: India City: Karnal | C432: DONE
A433: 45780 | B433: ~Bright Industries Group +91 94677 72559 Ambala, haryana mri , ct scan | C433: DONE
A434: 45780 | B434: Name: rabea Phone: +963992292474 Email: rabemnasfe@gmail.com Country: syria City: damascus Hospital/Clinic: philips Enquiry: hello price plwase | C434: will be handled by sir or ma'am/ Sachin Sir
A435: 45780 | B435: Otávio Pagnoncelli +5541992223607 Curitiba PR, Brazil (South America) looking for Siemens Essenza Dot warm system | C435: will be handled by sir or ma'am/ Sachin Sir
A436: 45782 | B436: Umer Ashraf 7006433996 Srinagar/Pulwama Jammu & Kashmir need CT scan refab | C436: DONE
A437: 45782 | B437: Akash Chaurasia (MD Radiodiagnosis) 9306801087 Panipat, Haryana | C437: DONE
A438: 45782 | B438: Ashu Naqvi +919818677916 Petct | C438: DONE
A439: 45782 | B439: Betim Sadriu +37744517811 Illinios--- (he has offices in Manaco(French region), Kosovo, Turkey and Bulgaria) Want to buy and sell multiple machines | C439: will be handled by sir or ma'am/ Sachin Sir
... A442: 45782 | B442: Dr Anu Radha +91 94193 70762 Jammu CT | C442: DONE
A443: 45782 | B443: Satish/ lalita +91 97831 95622 MRI | C443: DONE | D443: Not responding
A444: 45782 | B444: Deepak Pal +91 97933 57964 Maa Laxmi Pathology and Digital X-ray Lucknow, Uttar Pradesh Ct scanner | C444: DONE
A445: 45782 | B445: ~Mohammad Aijaj +91 99117 07250 (DocTrip India) Delhi Mri machines 1.5 t or 3 t | C445: DONE
A446: 45782 | B446: Ahmed Tharwat +201113797283 Cairo, Egypt (Africa) I need closed MRI 1.5 T Preferably Siemens avanto | C446: will be handled by sir or ma'am/ Sachin Sir
...

Sheet Leads 2024
A1: date | B1: details | C1: remarks
A2: 45293 | B2: Name- Dr Rajanish Singh Location- Uttar Pradesh Number- 8173843350 need- CT Scan Machine Source- Fb | C2: DONE
A3: 45302 | B3: 9994400936 What'sapp call preferred Language Tamil/ English only Nirmal Ratna Kumar From Ambur, Tamil Nadu Requirment - CathLab Machine | C3: DONE
A4: 45314 | B4: Name- Jhoan Diño, RXT, RRT Need- 5KH36MNA445X Email- jldmeddc@gmail.com (need quotation) Location- Philippines Part number 5KH36MNA445X Marathon carbonator pump motor. also need gradient power supply--- (part no.) GE MRI 5341543-52-R XFD | C4: DONE
A5: 45348 | B5: Dr. Rajesh Palani 8095100007 needs cathlab | C5: DONE
A6: 45351 | B6: Name- Mohammed Tauseef Need- MRI & CT (for new opening hospital) Number- 9319099177 Location- Saharanpur Source- Fb | C6: DONE
A7: 45351 | B7: Name- Kedar Yadav Contact - 009779869999908 Need- Part (5337137-8) Mega Switch ASSY_16 Channel Location-Janakpur Nepal Source-fb | C7: DONE
A8: 45351 | B8: Name- MD Khalaf Saba Contact: 8791204854 Need: 1.5T MRI machine Location- Aligarh Source- Linkedin | C8: DONE
A9: 45358 | B9: Name- Rahul Kumar Number- 7766873782 Need- CT Scan Profile - J.C.S Hospital Multi Speciality Location: Bihar | C9: DONE
A10: 45369 | B10: Name- Rakesh Vishwakarma Profile: Hetauda City Hospital Location: Bihar/Nepal Source- FB Need- CT Scan Numer- 9973029379 | C10: DONE
A11: 45372 | B11: Name- S.A Mir Phone Number- 9797282236 Location: Jammu kasmir Need : 1.5T MRI Machine Source- FB | C11: DONE
A12: 45384 | B12: Name-Carlos Lucky Number- +213672616931 (what up number) Need- CT Scanner Location- Constantine, Algeria | C12: DONE
A13: 45418 | B13: Name- Rajat Dhahiya Number: 8600090262 Location- Delhi Need- CT Machine Profile - Radilogist Doctor | C13: DONE
... A515: 45657 | B515: kamal +91 98250 79224 Rajkot gujarat refurb 1.5 tesla mri | C515: DONE
B517: New Leads will be added in 2025 ------Worksheet--- Switch to that sheet

Sheet after 25 july 2023
A1: Date | B1: details | C1: remarks
A2: 45136 | B2: facebook - 9960486644
A3: 45204 | B3: Name- Md Yunus Source- FB Query Mobile +8801614757307 Need- Cath lab or PET CT Profile- Director Media and Publications at Tour Operators Association of Bangladesh TOAB
A4: 45206 | B4: Name- Jeevan Shrestha Gmail- gbanstha@gmail.com Location- Former Medical Officer in the Medical oncology department at Nepal Cancer Hospital & Research Center Requirement- PET CT Source- FB Queery Want brochure/quotations on email first. Then he'll share contact detail
A5: 45206 | B5: Name- Sakham jain Number- 9041768058 Need- CT Scan Source- FB Profile- Consultant Neurologist at Park Group of Hospitals
A6: 45209 | B6: Name- Sanjeevani CBCC USA Cancer Hospital-SCCH Number- 9827198129 Need- MRI Machine Source- FB Profile- Sanjeevani CBCC USA Cancer Hospital-SCCH Location- Pachpedi Naka,, Raipur, India, Chhattisgarh
A7: 45210 | B7: Name- Naman Sharma Number- 9928365484 Requirement- CT Scan Location-Jaipur, Rajasthan (Apex Ranthambore Sevika Hospital)
A8: 45219 | B8: Name- Puspender Phone- 8696598283 Need- Refurbished ACT Revolution CT Machine Source- FB Location- Palwal
A9: 45219 | B9: Name- Dedarul Alam Rubel location- Bangladesh (Chittagong) Phone Number- +8801818782205 Sell - 2 (Quantity) GE Dead CT Scan Machine Source - FB wants to sell his CT
A10: 45220 | B10: Name- Jitendra Mehta Number- 7050780569 profile- MBBS,MD ( general physician ) Need- MRI Machine Source- Fb
A11: 45225 | B11: Name- Ajit Sihag Location- Tohana (Haryana) Need- CT Scan Number- 9467947575 Source- Fb
A12: 45225 | B12: Name- Anmol Sethi Mobile- 9871371100 Need - MRI & CT Location- Gurgaon, Haryana Profile Reference- dranmolsethi.com Source- Fb
A13: 45226 | B13: Name- Ranjit Bhandari Phone -9284838792 location- Batala Punjab Profile- Owner and MD Bhandari hospital Batala Punjab India Need- MRI OR CT Source- FB
... A32: 45287 | B32: Name- Jitu Kuamar Number- 8851066291 Location- Delhi Selling- Damaged MRI Machine (GE & Siemens) Source- Fb

Sheet after march 2023
A1: Date | B1: Source of Lead | C1: Requirement | D1: City | E1: STATE | F1: CENTER/ Hospital NAME | G1: CENTER ADDRESS | H1: Pincode | I1: CONTACT PERSON DETAIL | J1: E-MAIL ID | K1: Contact No | L1: REMARKS | M1: Lead Type | N1: Remark
A2: 44992 | B2: LinkedIn | C2: CT Scan | D2: Bhubaneswar, | E2: Orrisa | F2: Kalinga Institute of Industrial Technology, | G2: KIIT, Bhubaneshwar | I2: DR Mayank Goyal | K2: 9713586177 | L2: https://www.linkedin.com/in/dr-mayank-g-a9a395243/
A3: 44998 | B3: Facebook | C3: MRI 3.0T | D3: Dhangadhi | E3: Nepal | I3: Saroj Bhatta | K3: =9779825653891 -> 9779825653891
A4: 45002 | B4: Facebook | C4: CT Scan | D4: jaipur | E4: Rajasthan | F4: jay ct scan | I4: Naman sharma | J4: naman198811@gmail.com | K4: 9928365484
A5: 45005 | B5: Facebook | C5: Required Helium gas and machine | D5: Baroda | E5: gujarat | I5: Vikas Patel | J5: vpvp21340@gmail.com | K5: 8968630016
A6: 45005 | B6: Facebook | C6: Requriement 1.5T MRI | D6: Bangladesh | E6: Bangladesh | I6: MD Shamin Reza | J6: vpvp42182@gmail.com | K6: =8801711378071 -> 8801711378071
A7: 45008 | B7: LinkedIn | C7: Want- 1.5 MRI & Services | D7: kozhikode | E7: kerela | F7: medicare diagnostic | G7: FCC Building, Mavoor Rd, near Federal Bank Tower, Arayidathupalam, Kozhikode, Kerala 673016 | I7: Dileeps Raj | J7: 9895960485 | K7: 91 8943193513 Mr. Shahul Shoukkagh ( marketing person ) | L7: dileep.raj.janardhan@gmail.com
A8: 45012 | B8: Facebook | C8: Imaging Equipment | D8: Jodhpur | E8: Rajasthan | F8: Jain Nursing Home | G8: H-2/3, 3rd St, Adarsh Colony, Neelpur, Rajpura, Punjab 140401 | H8: 140401 | I8: Dr. Saksham Jain | J8: saksham60@gmail.com | K8: 9041768058 | M8: PNDT
A9: 45014 | B9: Facebook | C9: MRI | D9: Kabul | E9: Afghanistan | F9: Pamir Limited | I9: Mudasir / Mujibullah Alamyar | K9: =93700160336 -> 93700160336
A10: 45014 | B10: Facebook | C10: 1.5T HDXT MRI | D10: Deesa | E10: Gujarat | F10: Popularimaging Ct Scan | K10: 8141430532
A11: 45015 | B11: Facebook | C11: CT Scan | D11: ahamadanagar | I11: Yoges thorat | K11: 7276556935
A12: 45015 | B12: Facebook | C12: MRI Machine | D12: delhi | E12: Delhi | I12: Sumit Suneja | K12: 9810328140
A15: 45020 | B15: LinkedIN | C15: CT Scan | D15: South Delhi | F15: Dharmshila Hospital, Delhi | I15: Anup Kumar | K15: 9899925456 | L15: He is a radiotechnologist | M15: new center in Mathura
A16: 45020 | B16: Facebook | C16: 1.5T MRI | E16: Delhi | I16: Vikram Singh | K16: 8950748985
A17: 45021 | B17: Facebook | C17: MRI MACHINE | D17: Hapur/Delhi | E17: Uttar Pradesh / DELHI | I17: Jahid Khan | J17: khanjhaid281@gmail.com | K17: 7819977537
A18: 45028 | B18: Facebook | C18: want- CT Machine | D18: jaipur | E18: Rajasthan | I18: Nitesh choudhary | K18: 9772777282
A19: 45028 | B19: Facebook | C19: Want ct & Mri both | D19: PUNE | E19: Maharashtra | F19: New setup | I19: Mr. Yogesh Thorat | K19: 7276556935
A20: 45029 | B20: Facebook | C20: MRI & CT scan | D20: Delhi | E20: Delhi | I20: Shahid Khan | K20: 9416632141
A21: 45063 | B21: LinkedIN | C21: CT Scan | I21: Dr Kapil Saoji | K21: 8830289813
A22: 45063 | B22: LinkedIN | C22: Need A CT Scan Machine | I22: Dr Shah | K22: 9099097435
A23: 45063 | B23: LinkedIN | C23: Need A CT Scan Machine | I23: Devendra Rahangadae | K23: 8956776673
A24: 45064 | B24: LinkedIN | C24: Need- CT Scan | D24: Rampur, U.P | E24: Uttar Pradesh | F24: Director at Ganga hospital, | I24: Dr Muhammad Azeem | K24: 9359430202
A25: 45101 | B25: LinkedIN | C25: want to sell his cath lab to us | D25: Vadodara | E25: Gujrat | F25: Sarv multispeciality hospital | I25: Mr. Devang bhatt | K25: +91 99984 99696 and +91 6353 379 828
A26: 45102 | B26: LinkedIN | C26: Upgrade CT Machine of slice | D26: Gobara Ghati | E26: Odisha | F26: CENTER HEAD AT TATA STEEL MEDICA HOSPITAL | G26: XX8Q+8HG, Kalinga Nagar, PO: Madhuban, Gobara Ghati, Odisha 755026 | I26: Biswajit Dehury | J26: biswajit.dehury@medicasynergie.in | K26: Phone number- 09936832907
A27: 45103 | B27: LinkedIN | C27: need cath lab | D27: Chennai | E27: Tamil Nadu | I27: Dibin Mohammed Cardiac Surgeon | K27: 9895940242
A28: 45103 | B28: Twitter | C28: sell seiemens cath lab | D28: Aurangabad | E28: Maharashtra | F28: Pulse care medicine | I28: Khan Amer | K28: 9175646454
A29: 45106 | B29: LinkedIN | D29: New Delhi | E29: New Delhi | I29: Name- Dr (Capt) Sandeep Sharma | J29: sharma.sandeep1270@gmail.com | K29: 919810007751
A30: 45108 | B30: LinkedIN | C30: : imaging eqiupment | D30: Jaipur | E30: Rajasthan | F30: Amar Jain Hospital | I30: Dr Dharmendra Dudi | K30: 9571532980
A31: 45108 | B31: email | C31: amc for ct scan machine | D31: amroha | E31: uttar Pradesh | F31: alpha diagnostic and imaging Centre | I31: Qamrul | J31: alphadiagnosticamroha@gmail.com | K31: 9520867310

Sheet new lead
A1: Date | B1: Source of Lead | C1: City | D1: STATE | E1: CENTER NAME | F1: CENTER ADDRESS | G1: Pincode | H1: CONTACT PERSON DETAIL | I1: E-MAIL ID | J1: Contact No | K1: REMARKS | L1: Lead Type | O1: Follow-up 3
A2: 44453 | B2: Facebook ads | C2: Changuvetty, Kottakkal, Malappuram," | D2: Kerela | E2: ALMAS hospital kottakkal Kerela | F2: kottakkal Kerela, ((Planning for new centre in Karnataka)) | G2: 676503 | H2: DR. ADIL AHMED KARNUL NEUROSURGEON | J2: 9916567851 | K2: Mr Adil is planning for CT scan Machine going to open new centre in Karnataka this lead takes time of 4 months to close. But he want a call from Senior to know about site planning ,He is saying that as of now plan is cancel 14-April-2022 | O2: in touch on whatsapp
A3: 44454 | B3: Facebook ads | C3: Bharshi | E3: Pushpan Imaging Centre | F3: Siddheshwar Nagar, Barshi, Maharashtra | G3: 413401 | H3: Shirish Managolikar | I3: shirishmanagolikar@gmail.com | J3: 8147595492 | K3: He is planning for 3.0T MRI already have brand new 1.5T toshiba machine , he is a technician of the centre wants a call from manager and need every quotation of 3.0T, Not Connected 14-April-2022, He is saying there is not as such plan 06-April-2022 | L3: Followup
A4: 44455 | B4: Facebook ads | C4: Kolkata | D4: West Bengal | H4: Shantanu Mukherjee | J4: 9331721914 | K4: He is planning for CT scan But after 3 month he will ready to install MRI Machine , Not picked 14-April-2022, Not picked 06-April-2022, Wright now he is planning for anither machnie | L4: Followup
A5: 44488 | B5: Facebook ads | C5: Jhasi | D5: U.P | E5: Janta CT MRI centre | H5: CEO Ravi | I5: narangpreeti1109@gmail.com | J5: 9354624885 | K5: Planning for 1.5T MRI and want to install machine in jhashi Not picked 14-April-2022
A6: 44489 | B6: Facebook ads | C6: Kolkata | D6: West Bengal | H6: Dr Aditya | J6: 9123764577 | K6: Not picked 14-April-2022
A7: 44508 | B7: LinkedIn | C7: Halol | D7: Gujrat | E7: Gujrat Diagnostic Centre | F7: halol | H7: Shivang | I7: whatsappp | J7: 9429823457 | K7: planning for 1.5 Tesla, meeting fixed for January at gujrat, halol. | L7: LEAD
A8: 44508 | B8: LinkedIn | H8: Ashok Kumar Purohit | I8: ashok.nivari@gmail.com | J8: 7524099934 | K8: has diagnostic centre but not sure if he should expand his business in MRI/CT
A9: 44508 | B9: LinkedIn | D9: Andhra Pradesh | H9: Vinay Kumar Reddy | I9: Vinayreddy353@gmail.com | J9: 7989324097 | K9: not interested, first he told about his planning, but 2nd time he disconnected the call
A10: 44509 | B10: LinkedIn | C10: Kota | D10: Rajasthan | E10: Krishna Diagnostics | F10: Kota | H10: Ankesh Sharma | I10: shreea.k.balaji@gmail.com | J10: 9983336701 / 8005949830 | K10: In touch with Siemens | L10: LEAD
A11: 44513 | B11: LinkedIn | C11: Jamshedpur | D11: Jharkhand | E11: NGO | F11: Jamshedpur | H11: Md. SHAHNAWAZ | I11: mdshahnawaz8031@gmail.com | J11: 8409937767 | K11: He and his brother has a NGO which works for social service and community medical help in rural areas,-- not planning now, but shown some interst in coming months.
A12: 44516 | B12: LinkedIn | C12: Cohin | D12: Kerela | E12: -- | F12: Cohin | H12: nandha bharathi | I12: nbharathi511@gmail.com | J12: 8668174478 | K12: his senior doctor needs it, he is medical sale and purchase executive and related with multiple hospitals and medical centres, He will not give doctors number becoz doctor did not want to talk
A13: 44527 | B13: Facebook ads | H13: dr Gaurav kashyap | J13: =919837997268 -> 919837997268 | K13: I want ct scan machine Can you help me Gaurav Kashyap
A14: 44527 | B14: Facebook ads | C14: Imphal | D14: Manipur | F14: Imphal | H14: Rakib Yumakh | J14: 6009079600 | K14: did not pick up the call
A15: 44527 | B15: Facebook ads | C15: Ayodhya | D15: U.P | E15: Dr Sandeep Singh (Shyam Pharmacy) | H15: Apurv Rajey | J15: 9044000403 | K15: want to install MRI and is in Intial phase of discussion and comparing brochure from various dealers, Disconnected call 14-April-2022 | L15: LEAD
A16: DECEMBER
A17: 44531 | B17: LinkedIn | C17: Lukhnow | D17: U.P | E17: --- | F17: -- | H17: Dr parwaz ahmad khan | I17: khan1parwaz@yahoo.com | J17: 9919681319 | K17: he has an old ge x-ray machine and want to exchnage it for CT
A18: 44531 | B18: Facebook ads | C18: Sakoli | D18: Maharastra | E18: Dr Kapgate's dental clinic | F18: Sakoli | H18: Dr Dhananjay Kapgate's | I18: 8275298444 | J18: 9420684424 | K18: he is planning for 4 slice CT scans machine
A19: 44531 | B19: Facebook ads | C19: Srinagar | D19: Jammu Kashmir | H19: Firdous Ahmad Wani | J19: 9906067123 | K19: Very active plan for CT or MRI both He want all ddetails from us after that call again , He is saying he is busy so call after sometime 14-April-2022
A20: 44532 | B20: Facebook ads | C20: Hyderabad | D20: Andhra Pradesh | H20: Chiluvari Nagesh | J20: 9989509795 | K20: 1.5 MRI, meeting scheduled, not picked 10/12/2021, there is no plan 14-Aril-2022 | L20: LEAD
A21: 44532 | B21: Facebook ads | C21: saharanpur | D21: U.P | H21: Rao Amir Ali | J21: 9058808018 | K21: He is planning but conform after second call for the meeting , he is going to hospital tommorow and will beconnect call with the director Dr salman - 10/12/2021, He is saying therre is no plan14-April-2022
A22: 44532 | B22: Facebook ads | C22: / | D22: Jharkhand | E22: GBNR | F22: Majur ansari | H22: Md Jabbar Ansari | J22: 9931113822 | K22: He is planning for 1.5T Mri and want meeting , not picked 10/12/2021, He is saying that plan is there but there is a meeting after10 days where we decde we have install or not and director name is Majur ansari so call after15 days 14-April-2022
A23: 44536 | B23: Facebook ads | C23: belgavi | D23: Karnataka | E23: NCTs Nisarga Multispeciality | H23: Allam Prabhu | J23: 8722851234 | K23: He is planning for 1.5T Mri and 128 Slice and also prefer brand new machine but i told her that our machine is good an all he want all details and client list on whastapp then call after 2 days for the meeting shedule , not picked 10/12/2021, Not picked call i drop masg on whatsapp 14-April-2022 | L23: LEAD
A24: 44536 | B24: Facebook ads | C24: sardar sheher | D24: Rajasthan | E24: geetanjali diagnostis | H24: Ashkaran Soni | J24: 7727866129 | K24: Planning for Ct scan only
A25: 44536 | B25: Facebook ads | C25: pratapgarh | E25: prayag nursing home | H25: Arun Kumar Dwivedi | J25: 9452702944 | K25: He isplanning for MRI and Ct both But conformation after second call , he is planning for low than 16 slice machine budget is too low , Budget is low for machine14-April-2022
A26: 44536 | B26: Facebook ads | H26: Rahi Fayaz | J26: 9622737605 | K26: need brochure and quotation
A27: 44537 | B27: Facebook ads | C27: morena | D27: M.P | E27: bandil nursing home | H27: Sanjeev Bandil | J27: 9425334462 | K27: need 1.5/3 T mri in coming months-- follow up in few days, plan is cancel 14-April-2022
B28: Facebook ads | C28: Lalitpur | D28: u.p | E28: homesize ram clinic medical collage k pass | H28: Dr Rohit Sahu | J28: 6388142543 | K28: He is planning to start new setup in laltipur near medical collage there are more than one partner in this planning , this plan takes time so thats why call after 25 dec to take a followup , He is saying their is no plan 14-April-2022
A29: 44543 | B29: Facebook ads | H29: Dr Kamlesh Tripathi | J29: 9415046034 | K29: 64 slice CT 1 year, Not picked call 14-April-2022
A30: 44545 | B30: Facebook ads | C30: Aurangabad | D30: Maharashtra | E30: Sunshine hospital | H30: Nadeem Sheikh | J30: 9850633786 | K30: CT Scan 32 slice, planning in 3-4 months, He is saying he insstall the machine from pune centre 14-April-2022
A31: 44543 | B31: Facebook ads | C31: bangalore | D31: karnataka | E31: plasma medinostics | F31: Anekal Main Road, Chandapura, Bommasandra, Karnataka 560099 | H31: -Jay Kumar | J31: 7902915715 | K31: planning for Ct scan and mri both, whatsapp him, Not picked 14-April-2022 | L31: FOLLOWUP
A32: 44544 | B32: instagram | C32: Srinagar | D32: J&K | H32: Owais Khursheed | J32: 9797074767 | K32: plannig for ct and mri, but wants to disscuss price and details first , He is saying that call after sometime he is in market 14-April-2022
A33: 44546 | B33: Facebook ads | H33: Aaqib Sheikh | J33: 9906777781 | K33: on - 5 - jan dialed no. is currently busy ,
A34: 44547 | B34: Facebook ads | C34: pratapgarh | D34: u.p | E34: Plama diagnostics | H34: Prabhat Pandey | J34: 9565769090 | K34: plannig for ct and mri, but wants to disscuss price and details first , He is saying that planning is pospond for sometime call after2 months 14-April-2022 | L34: FOLLOWUP JUNE
A35: 44548 | B35: Facebook ads | C35: rajahmundi | D35: a.p | E35: tejendra diagnostic and x ray | H35: Kiran Kumar | J35: 7702578738 | K35: planning for CT only, in 2 months and wants details on whatsapp, He is saying that yes their a plan but i will call you after sometime14-April-2022
A36: 44548 | B36: Facebook ads | H36: Uma Shanker | J36: 9494469274 | K36: on - 5 - Jan Not answred the call
A37: 44550 | B37: Facebook ads | C37: Chennai | D37: tamil nadu | H37: Gibran Fazal, | J37: 9751999353 | K37: looking for single or dual slice ct only
A38: 44552 | B38: Facebook ads | D38: Jammu Kashmir | H38: Sushil Arora | I38: sushilarora2003@gmail.com | J38: 9419189485 | K38: on - 5 - jan - He want to install 3 Tesla machine in kashmir , he said he had worked with GE company it self for around 12 years as a dealer now he want to install him self he want the price range & clint details of north on his whats ap said he want to meet and talk firstabout the viability of machine asked about the finance ,he said he had teh site ready said site will be done after talking about the price & all .he said the are is shalara road . & he did not told me about the channels .Person is fake he is saying that what is MRI Suspense call throgh another call 14-April-2022 | L38: Followup
A39: 44552 | B39: Facebook ads | C39: naded | D39: Maharashtra | E39: Vishwaroop Hospital | F39: naded | H39: Ajabrao Kalbande | I39: ajabraokalbande@gmail.com | J39: 8624991387 | K39: on 5 - jan He said that there site is Under cunstruction & they will take around 1 yr to take MRI & CT scan Scan/ He also told his center workin under a private health care , But he did not dissclose full name of hospital. he wants branden , is busy as some work may be cause ther many noice of back ground he said he want only brand new But do not have any idia about machines he said he is thie one who is handeling the del & details he want brocchure & machines details on his mail id & whats ap also then he will talk he said . & his mail id is ajabraokalbande@gmail.com, he is saying send me all details on whatsapp then i ill confrom he is looking like fake but for verification call tommorow 14-April-2022 | L39: Followup
B40: Facebook ads | C40: lukhnow | D40: u.p | H40: Asif Ahmad | J40: 6387285680 | K40: wants to discuss with regional salesperson
...

Sheet old lead sheet
A1: S.No | B1: Date | C1: Requirement | D1: City | E1: State | F1: Hospital/Centre | G1: Person | H1: Contact no | I1: E-Mail ID | J1: Source | K1: Forwarded | L1: Remarks | M1: 14 september calls
A2: 1 | B2: 44316 | C2: CT Scan | D2: Ahmedabad | E2: Gujrat | G2: Jitendra Parmar | H2: =+919643158267 -> 919643158267 | J2: LinkedIN message | K2: yes -to ROCHI mam, Ritika mam, and Shivani Mam through Email | L2: Already in touch as told by Shivani Mam | M2: --
A3: 2 | B3: 44316 | C3: PET CT Scan | D3: Srinagar | E3: Jammu and Kashmir | G3: Mohammad Mustafa Bhat | H3: Find Number | J3: linkedin message | K3: yes -to ROCHI mam, Ritika mam, and Shivani Mam through Email | L3: his need was PET CT Scan | M3: --
A4: 3 | B4: 44315 | C4: CT Scan | D4: Chittaranjan - Bardhaman | E4: West Bengal | G4: Arindam Mukherjee | H4: 8293781255 | J4: Facebook message | K4: yes -to ROCHI mam, Ritika mam, and Shivani Mam through Email | M4: commission work
B5: 44331 | C5: job seeker | G5: Jyoti Sodhi Thakur | H5: Find Number | K5: - | L5: irrelevant
A6: 4 | B6: 44335 | C6: not sure | D6: Solapur | E6: Maharshtra | G6: Unknown Account | H6: =912184225474 -> 912184225474 | J6: Facebook comment | K6: Sent to ritika mam for verification | L6: --------- | M6: will contact if required
A7: 5 | B7: 44335 | C7: no info | D7: - | E7: - | G7: Neeraj Vashistha | H7: 7452009200 | J7: Facebook comment | K7: yes -to ROCHI mam, Ritika mam, and Shivani Mam through Email | M7: not connected
A8: 6 | B8: 44336 | C8: upgrading MRI | D8: Noida | E8: NCR- Delhi | G8: Dr. Navdeep | H8: 088007 78695 | J8: linkedin message | K8: yes -to ROCHI mam, Ritika mam, and Shivani Mam through Email | M8: contact on wahtaapp
A9: 7 | B9: 44337 | C9: not sure | D9: kathmadu | E9: Nepal | G9: Kalyan Sharma | H9: Find Number | J9: fb mesaage | K9: not in contact | L9: need to find contact | M9: ---
A10: 8 | B10: 44345 | C10: Tender for multiple products | D10: London | E10: England UK | F10: New Look Private Hospital | G10: Dr Harry Wang | H10: harry.wang.ceo@gmail.com | J10: linkedin message | K10: yes -to ROCHI mam, Ritika mam, and Shivani Mam through Email | M10: ----
A11: 9 | B11: 44349 | C11: MRI and CT Both | D11: New Delhi | E11: Delhi | G11: Dr Yudhveer | H11: 9811140057 | J11: twitter message | K11: yes -to ROCHI mam, Ritika mam, and Shivani Mam through Email | M11: Dr is saying yes there is a plan for 3.0T and want all details of that after that he want a followuo and want to shedule a meeting 14-April-2022, He want to connecte call on monday 15-April-2022
A12: 10 | B12: 44355 | C12: CT Scan | D12: aurangabad | E12: Maharshtra | F12: Future Teleradiology Solutions | G12: Dr. Mohammad Zeeshan | H12: 9970943371 | J12: linkedin message | K12: yes -to ROCHI mam, Ritika mam, and Shivani Mam through Email | M12: not connected
A13: 11 | B13: 44358 | C13: CT Scan | G13: Saksham Gupta | H13: 9423585733 | J13: fb ads | K13: yes -to ROCHI mam, Ritika mam, and Shivani Mam through Email | M13: He is saying that he is plan but call after sometime 13-April-2022
A14: 12 | B14: 44358 | C14: job seeker | G14: Yusuf C. Shaik | J14: fb ads | K14: not required | L14: irrelevnt | M14: ------
A15: 13 | B15: 44359 | C15: CT Scan | D15: Ghaziabad | E15: NCR Delhi | F15: SR Diagnostics | G15: Dr Rahul Kansal | H15: 9622127948 | J15: fb ads | K15: yes -to ROCHI mam, Ritika mam, and Shivani Mam through Email | M15: Not picked 13-April-2022, Not picked 14-April-2022, Rahul is saying that there is no requirement 30-April-2022
A16: 14 | B16: 44361 | C16: MRI | D16: Nashik | E16: Maharashtra | G16: Kishor Bhandari | H16: 9326013798 | J16: fb ads | K16: yes -to ROCHI mam, Ritika mam, and Shivani Mam through Email | M16: Done
A17: 15 | B17: 44361 | C17: MRI | D17: delhi | E17: NCR Delhi | F17: VR Diagnostics | G17: Dr. Ritesh Singh | H17: 8527086818 | J17: fb ads | K17: yes -to ROCHI mam, Ritika mam, and Shivani Mam through Email | M17: call after 6 pm in evening, Already in lead sheet ram sir is following 13-April-2022 | N17: Lead
A18: 16 | B18: 44361 | C18: business collab | D18: Mumbai | E18: Maharashtra | G18: Sonali Shelke | H18: Find Number | I18: medisurgi.resources@gmail.com | J18: fb ads | K18: yes -to ROCHI mam, Ritika mam, and Shivani Mam through Email | L18: may be irrelevant | M18: ---
A19: 17 | B19: 44370 | J19: fb ads | K19: direct wahtsapp to ritika mam | M19: ------
A20: 18 | B20: 44379 | C20: CT Machine | D20: Sitamadhi | E20: Bihar | F20: New | G20: Vinit Jha | H20: 9040441429 | I20: vinitjha35@gmail.com | J20: linkedin message | K20: yes -to ROCHI mam, Ritika mam, and Shivani Mam through Email | M20: He is saying that yes there is a planning for CT scans machne but for not current 30-April-2022
A21: 19 | B21: 44382 | C21: MRI Machine | D21: Thanjavur, | E21: Tamil Nadu | F21: Dr.Vanchilingam Hospital | G21: Somesh vanchilingam | H21: 9843077101 9442501101 04362226297 04362226658 | I21: drsomesh@hotmail.com | J21: linkedin message | K21: yes -to ROCHI mam, Ritika mam, and Shivani Mam through Email | M21: HE is saying yes there is a plan but in this month i will conform about the deal and also saying i saw your broucher and you all are in my mind 13-April-2022
A22: 20 | B22: 44386 | C22: CT Machine | D22: Nokhamandi | E22: Rajasthan | G22: Kishan Singh | H22: Find Number | J22: fb ads | K22: yes -to ROCHI mam, Ritika mam, and Shivani Mam through Email
A23: 21 | B23: 44391 | C23: not confirmed | D23: Sonipat | E23: haryana | F23: Sanjeevan x ray and 3d/4d colour doppler centre | G23: Satya Narain Kuchhal | H23: 9812040959 | J23: fb ads | K23: yes -to ROCHI mam, Ritika mam, and Shivani Mam through Email | M23: He is touh with sumit for CT scans machine
A24: 22 | B24: 44395 | C24: CT Machine | D24: Pathanamthitta | E24: kerela | G24: Saji AG | J24: fb ads | K24: yes -to ROCHI mam, Ritika mam, and Shivani Mam through Email | M24: --- | P24: All india institut of ayurveda sarita vihar
A25: 23 | B25: 44395 | C25: not confirmed | G25: Rahul Bandigi | J25: fb ads | K25: yes -to ROCHI mam, Ritika mam, and Shivani Mam through Email | M25: --- | P25: GE REFURB
A26: 24 | B26: 44395 | C26: not confirmed | D26: Warangal | G26: Rama Krashna | J26: fb ads | K26: yes -to ROCHI mam, Ritika mam, and Shivani Mam through Email | M26: ----
A27: 25 | B27: 44396 | C27: job seeker | D27: Srinagar | E27: Jammu and Kashmir | G27: Varsha Kour | H27: not needed | J27: fb ads | K27: irrelevent | M27: ----
A28: 26 | B28: 44396 | C28: CT Machine | D28: Mumbai | E28: Maharashtra | F28: Vice President - OsiriX Verticle | G28: Shashank Gupta | H28: 8007 360 099 | I28: Shashank@actonindia.com | J28: fb ads | K28: yes -to ROCHI mam, Ritika mam, and Shivani Mam through Email | M28: Not picked
A29: 27 | B29: 44401 | C29: CT Machine | D29: Patiala | E29: Punjab | G29: Chetna Dhamija | J29: fb ads | K29: yes -to ROCHI mam, Ritika mam, and Shivani Mam through Email
A30: 28 | B30: 44415 | C30: CT Machine | D30: Ahmedabad | E30: Gujrat | F30: ELITE RADIOLOGY SERVICES | G30: VISHAL GOSWAMI | H30: 9879353050 | J30: fb ads | K30: yes -to ROCHI mam, Ritika mam, and Shivani Mam through Email | M30: Disconnected call 30-April-2022
A31: 29 | B31: 44436 | C31: Collab | D31: Chandigarh | E31: Punjab & haryana | F31: Eminence Health Solutions | G31: Nitin Goyal | H31: 9041333100 | I31: dr.nitin@eminencehealth.co.in | J31: fb | K31: yes -to ROCHI mam, Ritika mam, and Shivani Mam through Email | M31: Switch off 30-April-2022

Sheet calls to do
A1: sl no . | B1: Date | C1: center name | D1: adress | E1: pincode | F1: contact Person name | G1: contact no. | H1: email id. | I1: Remarks
A2: 1 | B2: 44628 | F2: ajay mehta | G2: 9582962692 | H2: ajay.mehta22@yahoo.com | I2: on - 8 mar dialed no. is currently busy . , on - 10 mar dialed twice , Dialed no. is busy , Mr ajay mehta sir called us back said he is working now , so call back afround 6 - 6:30 pm. , no. is curr busy in evening , He is saying that planning will take time of 6 months 11-June-2022 | J2: call on 28- july
A3: =1+A2 -> 2 | B3: 44628 | C3: Saroj Hospital | D3: Medical College Gate No. 2, Near Palaria Hospital, Jhansi | E3: 284001 | F3: Dr Dinesh Rajput | G3: 9455719038 | H3: drdin03@gmail.com | I3: on - 8 mar Dr did not answered the call ., on - 10 mar Dr rajput sir answered the call , Said they have CT scan , & USG machine they are looking for an MRI machine in 1.5T MRI machine , He is not sure about any channels But he said he want our site executive to visit his center , for this discussion . said he will discuss all the Details Face to face , & he is also agree to share his adress if we said him hello , on whats ap . Not picked 11-June-2022
A4: =1+A3 -> 3 | B4: 44628 | C4: VENNELA SCAN CENTRE & DIAGNOSTICS | D4: Door No 29-13-91, Nakkal Road, Kaleswara Rao Road, Suryarao Pet, , Vijayawada | E4: 520002 | F4: Dr Sujatha Deva | G4: 9392135185 | I4: on - 8 mar dr sujatha mam answered the call , she said she is looking for single slices CT scanner she does not have Plan for any Model so i told her That we do not deal in single slice CT , THere is no plan for MRI machine Right now.
A5: =1+A4 -> 4 | B5: 44628 | F5: Dr Raj Aras | G5: 9360936100 | I5: on - 8 mar dialed no is switched off. , on - 10 mar dialed no is curr. switched off , , on - 25 mar dialed no. is curr . switched off. , Switch off 11-June-2022
A6: =1+A5 -> 5 | B6: 44628 | F6: Shabarish reddy | G6: 9902222173 | H6: shabarishreddy121@gmail.com | I6: on - 8 mar dialed Dr shabarish sir answer the call , said he is looking for either 4 slices refurb CT scan , or 16 slices , He is agree with our Price Segment , Want Brochure Over whats ap , Said he will call us in like 15 mins . , he called me back said he is looking for 4 slices CT scan , AS there is not much patients around his hospital .
A7: =1+A6 -> 6 | B7: 44628 | F7: Gauribidanur From Gauribidanur (Karnataka)
A8: =1+A7 -> 7 | B8: 44628 | C8: Nagercoil , Tamilnadu | F8: Dr. Sheju Jonathan | G8: 9943653641 | H8: shejujj@gmail.com | I8: on - 8 mar Dr said he actually is not looking for any machines right now. it is only a mistake he said .
A9: =1+A8 -> 8 | B9: 44628 | F9: Nagaraj Raj , Synagaraj Raj | G9: 8884044912 | H9: synagarajpranav@gmail.com | I9: on - 8 mar did not answered , on - 10 mar dialed no is curr .Busy .
A10: =1+A9 -> 9 | B10: 44628 | F10: Keerthipati Vd Kumar | G10: 9849247626 | H10: klnsimha143@gmail.com | I10: on - 8 mar Dialed no. is curr. busy after ringing , on - 10 mar dialed no. is curr . Busy after ringing .
A11: =1+A10 -> 10 | B11: 44628 | C11: firojabad | F11: Dr B.s Yadav | G11: 9719700801 | H11: dr.bhoopendra7284@gmail.com | I11: on - 8 mar Dr B.s yadav said he is looking for 64 slices CT scan , center is under cunstrction , Did not confirm Much Details about timing & all said , he want Brocchure & machine details on his whats ap first . then he will contact us . , Not picked 23-Sept-2022 | J11: Send me prices ccontact me ,
A13: =1+'Followups '!A1 -> 12 | B13: 44628 | C13: Nitin Sawale City Hospital | D13: Buldana Behind Bus Stand ,Jamrun Road Buldana | E13: 443001 | F13: Nitin Sawal | G13: 9822697790 | H13: sawalenitin633@gmail.com | I13: on - 8 mar Dr said they have Already done a meeting & site enginer is also visited here ,It mean he is already in touch with our company | J13: we are planning to purchase MRI and CT Scan M/C
A14: =1+A13 -> 13 | B14: 44628 | C14: Indeess Medical Systems Inc | D14: No 744/1a 3rd floor, Tiruchendur road, Palayamkottai, Tirunelveli , Near Law College Opposite | E14: 627011 | F14: Bipin Kumar Singh | G14: 8294028777 | I14: on - 10 mar he have a center on name of indeess medical system . THey are actually a dealer
A15: =1+A14 -> 14 | B15: 44628 | C15: Showket Zargar | D15: SRL Diagnostics, Srinagar/Baramulla | G15: 9906834665 | I15: on - 10 mar dialed no. is not answering the call
A16: =1+A15 -> 15 | B16: 44628 | C16: Nirmal Patil Chetna Hospital | D16: https://www.linkedin.com/in/nirmal-patil-82a715135/ | I16: Hello, we are looking for investor to start radio diagnostic centre. Please call 8554990324 in evening
A18: =1+'Followups '!A2 -> 17 | B18: 44630 | C18: Pranav hospital | D18: Gandhi Maidan, Near Handady Grama Panchayat, Handady, Bramavara, Karnataka | E18: 576213 | F18: Praveen Kumar | G18: 9880722819 | I18: on - 10 mar He said he is looking for 1.5 T he asked me the Starting price & told me to call back after tuesday to talk to him , Dr is saying that he is planning for 1.5T MRI wants to meet someone from our side 12-April-2022, he is saying that no plan as such right now 23-Sept-2022 | J18: LEAD
A19: =1+A18 -> 18 | B19: 44630 | C19: KANNUR MEDICAL COLLEGE | D19: Integrated Campus, PO, Anjarakandy, Kerala | E19: 670612 | F19: Dr Ilango Parthasarathy | G19: 9585528583 | H19: sp.ilangodoctor@gmail.com | I19: on - 10 mar Dr said they are cunstructing there hospital , It will take september to complete there hospital , Before Then They are looking to install All the machines , execpt MRI , He said MRI will take some more Time., He said he is looking for eithere 64 slices or 128 slices CT scan He want the Details And tube knowledge of the machines on whats ap . Then after after 2 days he want call back to talk . , So basically he can close the Deal first Because they want to start the hopsital in October , so he have more time to install . , Disconnected the call 23-Sept-2022 | J19: LEAD
A20: =1+A19 -> 19 | B20: 44630 | C20: Bhanu radiology clinic Chhindwara | D20: Uday Tower, Khajri Road (Nagpur Road), Chhindwara HO, Chhindwara - , Infront Of Dist.hospital Gate No 03 ,Behind City Kotwali Police Station ,Near Gourav Lodge Bhudhwari | E20: 480001 | F20: Dr Bhanu Pratap | G20: 9479718859 | H20: doctorbhanu14@gmail.com | I20: on - 10 mar Dr bhanu said he is looking for 1.5T Basic model , He said they will take around 6 - 8 months to install MRi , at Present he want the Basic 1.5 T HDE model & 1.5 T creator model to compare , HE want installation list in MP , To discuss our review , & then , He will Proceed to meeting ,., He has a plan but will take time of 6b months call after 1 months 19-march-2022, Dr is saying that yes their is a plan but he is confuse that he will go with brand new or refub he want to meet someone in nagpur tommorow 13-April-2022, He is sayijng tha he is facing some issue in the site thats why plan gets dealy he is telling he is touch with our engineers and feils exectiuive well so plan is take time of 2 months 22-Sept- | J20: LEAD
A21: =1+A20 -> 20 | B21: 44630 | C21: Sharma Diagnostic Centre | D21: Ram bhavan, Dadri-Jarcha Rd, Aurangabad, Uttar Pradesh | E21: 203207 | F21: Umesh Sharma | G21: 9350110289 | I21: on - 10 mar dialed no. is busy on another call , Then he answered the call & disconnected it . | M21: planning for CT scans in greater noida dadli
A22: =1+A21 -> 21 | B22: 44630 | C22: Hill Maxx Diagnostic Laboratory | D22: Jammu | F22: Manik Mahajan | G22: 8717051111 | I22: on - 10 mar manik said he already speaked with rochi mam , & was planning for .04 T MRI , So he said now, he have taken , 0.4 T MRI machine , did not disclose the Company , But said , that if in future he is planning for a supercon , Then He will contact us . | M22: Not connected
A23: =1+A22 -> 22 | B23: 44630 | F23: Omar Mukhtar | G23: 6005496663 | I23: on - 10 mar did not answered the call . | M23: Disconnect the call
A24: =1+A23 -> 23 | B24: 44630 | F24: Ravinder Kalra | G24: 9997319911 | I24: on - 10 mar dialed no. is Busy on another call , then The dialed no. is busy
A25: =1+A24 -> 24 | B25: 44630 | F25: Gaurav Giri | G25: 8006009599 | I25: on - 10 mar did not answered the call . | M25: Busy on another call
A26: =1+A25 -> 25 | B26: 44630 | F26: Santanu Kumar Ghosh | G26: 9775070692 | I26: on - 10 mar dialed no. is curr.Busy
A27: =1+A26 -> 26 | B27: 44630 | F27: Dr.PrithvirajPatil | G27: 8275480481 | H27: prithvipatil777@gmail.com | I27: on - 10 mar Dr pritvi raj sir answered the call , Said he was Previously planning But Now , he said The pnning is not executing , so he will take time , He said he will contact us when ever there is any plan . | M27: Not picked
A28: =1+A27 -> 27 | B28: 44630 | C28: Aayush Laboratory | D28: Aayush Laboratory, Medical College, Calicut | E28: 695011 | F28: Nidheesh Pk | G28: 9961339952 | I28: on - 10 mar Dr nideesh sir answered sid he is Planning for CT scan machine right now He said he want know Which machine will good for him. | J28: Presently I am running a laboratory www.leaayush.com I am planning to start a CT and usg
A29: =1+A28 -> 28 | B29: 44630 | F29: Jitendra Kumar Mahajan | G29: 9795639336 | I29: on - 10 mar He said he busy now , want us to call back in evening , But By searching found he is , konika minolta Business solutions .
A30: =1+A29 -> 29 | B30: 44630 | F30: Gobinda Reang | G30: 8974503457 | I30: on - 10 mar Mr. gabinda Is actually Was in inrolled in a cource & that they will take time right now. HE said at Present there is no plan , But when ever there is any Plan he will contact us . | J30: not now.....but I want to know ...my... whatsapp no... - Assam
A31: =1+A30 -> 30 | B31: 44630 | F31: Parveen Gupta | G31: 888139521 | I31: on - 10 mar No. is incorrect, no. is inavalid.
A32: =1+A31 -> 31 | B32: 44630 | F32: Bhat Farooq | G32: 7889979841 | I32: on - 10 mar Dialed no. did not answered the call.
A33: =1+A32 -> 32 | B33: 44630 | F33: Shivam Dwivedi | G33: 77048 63074 | H33: shivamdwivedi461@gmail.com | I33: on - 10 mar shivam Sir answered the call , Said at Presnt there is no plan , Previously they were planning But due to financial Isuue He is Presently Not planning . | M33: shivam is saying their is no plan due to finance
A34: =1+A33 -> 33 | B34: 44630 | F34: Dar Mansoor | G34: 7051748554 | I34: on - 10 Mar dialed no. did not answered the call ,
A35: =1+A34 -> 34 | B35: 44630 | F35: Amit Singh | G35: 8859515194 | I35: on - 10 Mar dialed no. did not answererd the call. , on - 19 mar dialed no is curr . busy after single bell. | M35: He is planning to install machine in uttrakhand in vinayak hospital 8859515194
A36: =1+A35 -> 35 | B36: 44630 | F36: Sunil Gupta | G36: 9450086024 | I36: on - 10 mar incomming call facility is not available . | M36: He is planning for 4 slice Ct scans machine
A37: =1+A36 -> 36 | B37: 44630 | F37: Jitendra Sharma | G37: 7987088647 | I37: on - 10 mar dialed no. did not answered the call.
A38: =1+A37 -> 37 | B38: 44630 | F38: Amit Thakur - MRI | G38: 9161232323 | I38: on - 10 mar dialed no. disconnected the call after answering .
A39: =1+A38 -> 38 | B39: 44630 | F39: Mritunjay Raj | G39: 9931862385 | I39: on - 10 mar Mr mritunjay sir answered the call , said he is looking for single slice CT scan . only in refurb .
A41: =1+'Followups '!A3 -> 40 | B41: 44630 | F41: Chenthil Pillai | G41: 9894953210 | I41: on - 10 mar dialed no did not answered the call
A42: =1+A41 -> 41 | B42: 44630 | F42: Lalit | G42: 9940027564 ,8610854140 | H42: drlalithasekar@gmail.clm | I42: on - 10 mar dialed no. is busy on another call , 6slices USG , Dr lalthila mam Called us back , She said she has a cunsultancy Services they are actually help Dr;s To open Diagnostic center , & they are like a dealer in south Region , SHe said he is looking For a partner ship ( collab ) for refurb CT scanner machines. | M42: Mrs lalit is the concern person here and want 32 sliceCt scans machine want broucher an all
A43: =1+A42 -> 42 | B43: 44630 | C43: medity Diagnostic center | D43: karnal | F43: Satender Khatri | G43: 9813075457 | H43: dr.satender@yahoo.com | I43: on - 10 mar dialed no. Mr. satender sir said he is planning for Both MRI & CT scan MRi in 1.5 T 16 channels & 16 slices Brand new CT scan , He wants to install with in 6 months , Now he want 1.5T Brocchure & raw quotation as well as philips 16 slices CT scan quotation & blue Print for MRI & CT scan . he has an architecht , now, want to talk it out first .He is saying that call me after 2 months he is outside from town 07-May-2022, Disconnected the call 23-Sept-2022, He is saying that he is out of station for one month so he told me to call after one months so call on 2 nov 07-Octo-2022
...

Sheet Followups 
A1: =1+'calls to do'!A11 -> 11 | B1: 44628 | C1: Osmania Medical College | D1: 5-1-876, Turrebaz Khan Rd, Troop Bazaar, Koti, Hyderabad, Telangana | E1: 500095 | F1: Ravi Teja | G1: 9000160610 | H1: athkuriraviteja@gmail.com | I1: on - 8 mar dialed no. did not answered the call . , on - 10 mar He said that his Friend is looking for 16 slices Rfurb CT scan he want the Details of Brightspeed on whats first then he will talk to us he said , he did not Disclose any details also , He is saying please send me the details of machine on whatsapp then after i will tell you about the plan 23-Sept-2022
